<!-- Notes: -->
<!-- FR = Front Right, FL = Front Left, BR = Back Right, BL = Back Left -->


<mujoco model="Quadroped">
    <compiler angle="radian" />

    <!-- Settings -->
    <option timestep = "1e-4"/> 
    <option gravity="0 0 -9.81"/>



    <asset>
        <!-- CAD Files -->
        <mesh name="Body-v1" file="meshes/Body-v1.stl" scale="0.001 0.001 0.001" />
        <mesh name="Lower-leg-1" file="meshes/Lower-leg-1.stl" scale="0.001 0.001 0.001" />
        <mesh name="Upper-leg-1" file="meshes/Upper-leg-1.stl" scale="0.001 0.001 0.001" />
        <mesh name="Upper-leg-2" file="meshes/Upper-leg-2.stl" scale="0.001 0.001 0.001" />
        <mesh name="Lower-leg-2" file="meshes/Lower-leg-2.stl" scale="0.001 0.001 0.001" />
        <mesh name="Upper-leg-3" file="meshes/Upper-leg-3.stl" scale="0.001 0.001 0.001" />
        <mesh name="Lower-leg-3" file="meshes/Lower-leg-3.stl" scale="0.001 0.001 0.001" />
        <mesh name="Upper-leg-4" file="meshes/Upper-leg-4.stl" scale="0.001 0.001 0.001" />
        <mesh name="Lower-leg-4" file="meshes/Lower-leg-4.stl" scale="0.001 0.001 0.001" />
        
        <!-- World Files -->
        <texture type="skybox" builtin="gradient" rgb1=".3 .5 .7" rgb2="0 0 0" width="32" height="512"/>
        <texture name="grid" type="2d" builtin="checker" width="512" height="512" rgb1=".1 .2 .3" rgb2=".2 .3 .4"/>
        <material name="grid" texture="grid" texrepeat="1 1" texuniform="true" reflectance=".2"/>
    </asset>

    <worldbody>
        <!-- World Plane -->
        <geom name="floor" size="0 0 .05" type="plane" material="grid"/>
        <light name="spotlight" mode="targetbodycom" target="Body-v1" diffuse=".8 .8 .8" specular="0.3 0.3 0.3" pos="0 -6 4" cutoff="30"/>
        <light name="top" pos="0 0 2" mode="trackcom"/>

        <!-- Wrapper to rotate the robot to the right axis -->
        <body name="wrapper" pos="0 0 0" euler="1.57 0 0">
            <!-- Enables Gravity for the Body -->
            <joint type = "free"/> 

            <!-- Parent Body for Robot -->
            <body name="Body-v1" pos="0.0 0.5 0.0" euler="-0.0 0.0 -0.0">

                <!-- Body -->
                <geom name="Body-v1_geom" type="mesh" mesh="Body-v1" pos="0 0 0" euler="0 0 0" />
                <inertial mass="28.28466150233067" pos="0.0 2.5241714164863475e-18 0.0" fullinertia="0.8533001622699443 0.9026775472629809 0.056913693261835374 -2.2846506908535957e-17 -1.8277205526828766e-16 0.0" />

                <!-- Front Right Leg -->
                <body name="Upper-leg-4" pos="-0.07700000000000002 -0.06890000000000006 0.265" euler="-0.0 -1.5707963267948963 0">
                    <joint name="FR-Hip" type="hinge" axis="0.0 0.0 1.0" pos="0.0 0.06890000000000006 0.004999999999999992" damping = '0.0'/>
                    <geom name="Upper-leg-4_geom" type="mesh" mesh="Upper-leg-4" pos="0 0 0" euler="0 0 0" />
                    <inertial mass="0.4063882488346593" pos="-1.5880630144238238e-14 9.658940314238862e-17 0.005" fullinertia="0.0010478475656508172 3.471342654052731e-05 0.0010757878547107726 -8.673617379884035e-19 -1.925929944387236e-34 2.0251590889358678e-19" />
                    <body name="Lower-leg-4" pos="0.0 -0.13779999999999998 0.022" euler="-3.141592653589793 0.0 -3.141592653589793">
                        <joint name="FR-Knee" type="hinge" axis="0.0 0.0 -1.0" pos="8.437816446125266e-18 0.06890000000000002 0.010000000000000035" damping = '0.0'/>
                        <geom name="Lower-leg-4_geom" type="mesh" mesh="Lower-leg-4" pos="0 0 0" euler="0 0 0" />
                        <inertial mass="0.4248843755826693" pos="-2.2772772242371458e-14 0.0009997881825223242 0.005145107138247074" fullinertia="0.0011361051854464274 3.5590752875500065e-05 0.0011633993497458112 6.590601467234604e-16 -1.735236150243669e-18 -4.186303079975569e-06" />
                    </body>
                </body>

                <!-- Front Left Leg -->
                <body name="Upper-leg-1" pos="0.087 -0.0689 0.265" euler="-0.0 -1.5707963267948963 0">
                    <joint name="FL-Hip" type="hinge" axis="0.0 0.0 1.0" pos="0.0 0.0689 0.01" damping = '0.0'/>
                    <geom name="Upper-leg-1_geom" type="mesh" mesh="Upper-leg-1" pos="0 0 0" euler="0 0 0"/>
                    <inertial mass="0.4063882488346593" pos="-1.5880630144238238e-14 9.880984919163893e-17 0.005" fullinertia="0.0010478475656508172 3.471342654052731e-05 0.0010757878547107726 -8.67361737988404e-19 -1.7347234759768069e-18 6.648458290948168e-19" />
                    <body name="Lower-leg-1" pos="0.0 -0.13780000000000034 -0.013000000000000125" euler="-0.0 0.0 -0.0">
                        <joint name="FL-Knee" type="hinge" axis="0.0 0.0 1.0" pos="0.0 0.06890000000000077 0.020000000000000295"  damping = '0.0'/>
                        <geom name="Lower-leg-1_geom" type="mesh" mesh="Lower-leg-1" pos="0 0 0" euler="0 0 0" />
                        <inertial mass="0.4248843755826693" pos="-2.2737367544323207e-14 0.0009997881825222943 0.005145107138247155" fullinertia="0.001136105185446424 3.559075287549352e-05 0.0011633993497458311 6.522560269672831e-16 -1.7347234759769616e-18 -4.186303079975615e-06" />
                    </body>
                </body>

                <!-- Back Right Leg -->
                <body name="Upper-leg-3" pos="-0.08799999999999998 -0.06890000000000006 -0.265" euler="-1.2246467991473532e-16 1.5707963267948963 0">
                    <joint name="BR-Hip" type="hinge" axis="-0.0 -2.220446049250313e-16 -1.0" pos="8.43781644612527e-18 0.06890000000000006 0.009999999999999966" damping = '0.0'/>
                    <geom name="Upper-leg-3_geom" type="mesh" mesh="Upper-leg-3" pos="0 0 0" euler="0 0 0" />
                    <inertial mass="0.4063882488346593" pos="-1.5880630144238238e-14 9.880984919164088e-17 0.005" fullinertia="0.0010478475656508172 3.471342654052731e-05 0.0010757878547107726 -9.91434886045236e-19 2.7401312609146714e-34 6.648458290948168e-19" />
                    <body name="Lower-leg-3" pos="-3.552713678800501e-17 -0.13779999999999998 -0.012" euler="-0.0 0.0 -0.0">
                        <joint name="BR-Knee" type="hinge" axis="0.0 0.0 -1.0" pos="8.437816446125266e-18 0.06890000000000002 0.009999999999999993"  damping = '0.0'/>
                        <geom name="Lower-leg-3_geom" type="mesh" mesh="Lower-leg-3" pos="0 0 0" euler="0 0 0" />
                        <inertial mass="0.4248843755826693" pos="-2.2737245105583453e-14 0.0009997881825223242 0.005145107138247091" fullinertia="0.0011361051854464274 3.559075287547925e-05 0.0011633993497458042 6.555906997715068e-16 -1.735236150243668e-18 -4.186303079977304e-06" />
                    </body>
                </body>

                <!-- Back Left Leg -->
                <body name="Upper-leg-2" pos="0.07700000000000007 -0.06889680384218429 -0.26433635828063684" euler="0.009632104227912582 1.5707963267948963 0">
                    <joint name="BL-Hip" type="hinge" axis="-2.138723706643446e-18 2.2203430464056605e-16 -1.0" pos="1.3042952135000618e-16 0.06890000000000059 -5.40907754493371e-17"  damping = '0.0'/>
                    <geom name="Upper-leg-2_geom" type="mesh" mesh="Upper-leg-2" pos="0 0 0" euler="0 0 0" />
                    <inertial mass="0.4063882488346593" pos="-1.5882192595877925e-14 8.572535798946927e-17 0.005000000000000009" fullinertia="0.0010478475656508083 3.4713426540532954e-05 0.0010757878547107795 8.876905287225068e-19 -3.4692262534502614e-18 -2.6457179465415943e-19" />
                    <body name="Lower-leg-2" pos="-7.105427357601002e-17 -0.13780000000000023 0.022" euler="3.141592653589793 0.0 -3.141592653589793">
                        <joint name="BL-Knee" type="hinge" axis="0.0 0.0 1.0000000000000013" pos="-2.872043445458069e-07 0.06889961043263586 0.010000000000000045"  damping = '0.0'/>
                        <geom name="Lower-leg-2_geom" type="mesh" mesh="Lower-leg-2" pos="0 0 0" euler="0 0 0" />
                        <inertial mass="0.4248843755826693" pos="-2.2722853126552235e-14 0.00099978818252233 0.00514510713824708" fullinertia="0.001136105185446433 3.5590752875494664e-05 0.001163399349745842 6.511514960040599e-16 -4.959809252907669e-18 -4.186303079976195e-06" />
                    </body>
                </body>

            </body>


            <!-- End of Wrapper Body -->
        </body>
    

        <!-- End of WorldBody -->
    </worldbody>

        <!-- motors -->
    <actuator>
        <!-- Front Right -->
        <position name="FR-H-servo" joint = "FR-Hip" kp = '100'/>
        <position name="FR-K-servo" joint = "FR-Knee" kp = "100"/>

        <!-- Front Left -->
        <position name="FL-H-servo" joint = "FL-Hip" kp = '100'/>
        <position name="FL-K-servo" joint = "FL-Knee" kp = "100"/>

        <!-- Back Right -->
        <position name="BR-H-servo" joint = "BR-Hip" kp = '100'/>
        <position name="BR-K-servo" joint = "BR-Knee" kp = "100"/>

        <!-- Back Left -->
        <position name="BL-H-servo" joint = "BL-Hip" kp = '100'/>
        <position name="BL-K-servo" joint = "BL-Knee" kp = "100"/>

        <!-- <motor name="FR-H-servo" gear="40" joint="FR-Hip"/> -->
    </actuator>
        
    

    <!-- File Definition End -->
</mujoco>